------------------------------------------------------------------------
Traceback (most recent call last):
  File "circuitpython/traceback_test_chained.py", line 25, in <module>
RuntimeError: 
------------------------------------------------------------------------

------------------------------------------------------------------------
Traceback (most recent call last):
  File "circuitpython/traceback_test_chained.py", line 23, in <module>
ZeroDivisionError: division by zero

The above exception was the direct cause of the following exception:

Traceback (most recent call last):
  File "circuitpython/traceback_test_chained.py", line 25, in <module>
RuntimeError: 
------------------------------------------------------------------------


------------------------------------------------------------------------
OSError: 

The above exception was the direct cause of the following exception:

Traceback (most recent call last):
  File "circuitpython/traceback_test_chained.py", line 35, in <module>
RuntimeError: 
------------------------------------------------------------------------


------------------------------------------------------------------------
Traceback (most recent call last):
  File "circuitpython/traceback_test_chained.py", line 43, in <module>
ZeroDivisionError: division by zero

During handling of the above exception, another exception occurred:

Traceback (most recent call last):
  File "circuitpython/traceback_test_chained.py", line 45, in <module>
RuntimeError: 
------------------------------------------------------------------------


------------------------------------------------------------------------
Traceback (most recent call last):
  File "circuitpython/traceback_test_chained.py", line 54, in <module>
RuntimeError: 
------------------------------------------------------------------------

------------------------------------------------------------------------
Traceback (most recent call last):
  File "circuitpython/traceback_test_chained.py", line 60, in <module>
RuntimeError: 

During handling of the above exception, another exception occurred:

Traceback (most recent call last):
  File "circuitpython/traceback_test_chained.py", line 62, in <module>
ZeroDivisionError: division by zero
------------------------------------------------------------------------

------------------------------------------------------------------------
Traceback (most recent call last):
  File "circuitpython/traceback_test_chained.py", line 70, in <module>
  File "circuitpython/traceback_test_chained.py", line 68, in <module>
ZeroDivisionError: division by zero
------------------------------------------------------------------------

------------------------------------------------------------------------
Traceback (most recent call last):
  File "circuitpython/traceback_test_chained.py", line 70, in <module>
  File "circuitpython/traceback_test_chained.py", line 68, in <module>
ZeroDivisionError: division by zero
------------------------------------------------------------------------


------------------------------------------------------------------------
Traceback (most recent call last):
  File "circuitpython/traceback_test_chained.py", line 83, in <module>
Exception: inner

During handling of the above exception, another exception occurred:

Traceback (most recent call last):
  File "circuitpython/traceback_test_chained.py", line 85, in <module>
SomeException: outer
------------------------------------------------------------------------

------------------------------------------------------------------------
Traceback (most recent call last):
  File "circuitpython/traceback_test_chained.py", line 91, in <module>
Exception: inner

The above exception was the direct cause of the following exception:

Traceback (most recent call last):
  File "circuitpython/traceback_test_chained.py", line 94, in <module>
SomeException: outer
------------------------------------------------------------------------


------------------------------------------------------------------------
Traceback (most recent call last):
  File "circuitpython/traceback_test_chained.py", line 101, in <module>
RuntimeError: inner

The above exception was the direct cause of the following exception:

Traceback (most recent call last):
  File "circuitpython/traceback_test_chained.py", line 103, in <module>
Exception: outer
------------------------------------------------------------------------

------------------------------------------------------------------------
Traceback (most recent call last):
  File "circuitpython/traceback_test_chained.py", line 109, in <module>
RuntimeError: inner

The above exception was the direct cause of the following exception:

Traceback (most recent call last):
  File "circuitpython/traceback_test_chained.py", line 112, in <module>
Exception: outer
------------------------------------------------------------------------


------------------------------------------------------------------------
Traceback (most recent call last):
  File "circuitpython/traceback_test_chained.py", line 119, in <module>
RuntimeError: inner

During handling of the above exception, another exception occurred:

Traceback (most recent call last):
  File "circuitpython/traceback_test_chained.py", line 121, in <module>
SomeException: outer
------------------------------------------------------------------------

------------------------------------------------------------------------
Traceback (most recent call last):
  File "circuitpython/traceback_test_chained.py", line 127, in <module>
RuntimeError: inner

The above exception was the direct cause of the following exception:

Traceback (most recent call last):
  File "circuitpython/traceback_test_chained.py", line 130, in <module>
SomeException: outer
------------------------------------------------------------------------


